<mujoco model="yam_bimanual">
  <compiler angle="radian" meshdir="../yam/assets/"/>

  <size nkey="1"/>

  <default>
    <default class="left_main">
      <joint armature="0.1" damping="0.5"/>
      <geom contype="0" conaffinity="0"/>
    </default>
    <default class="right_main">
      <joint armature="0.1" damping="0.5"/>
      <geom contype="0" conaffinity="0"/>
    </default>
  </default>

  <asset>
    <mesh name="left_base" file="base.stl"/>
    <mesh name="left_link1" file="link1.stl"/>
    <mesh name="left_link2" file="link2.stl"/>
    <mesh name="left_link3" file="link3.stl"/>
    <mesh name="left_link4" file="link4.stl"/>
    <mesh name="left_link5" file="link5.stl"/>
    <mesh name="right_base" file="base.stl"/>
    <mesh name="right_link1" file="link1.stl"/>
    <mesh name="right_link2" file="link2.stl"/>
    <mesh name="right_link3" file="link3.stl"/>
    <mesh name="right_link4" file="link4.stl"/>
    <mesh name="right_link5" file="link5.stl"/>
  </asset>

  <worldbody>
    <geom pos="-0.0374966 0.303599 0.187501" quat="0.707105 0 0.707108 0" type="mesh" contype="0" conaffinity="0" rgba="0.317647 0.121569 0.498039 1" mesh="left_base"/>
    <body name="left_link1" pos="0 0.35 0.067" quat="0.707105 0 0 -0.707108">
      <inertial pos="-0.00261782 0.00744082 0.0237251" quat="0.602276 0.365837 0.642523 0.300984" mass="0.104154" diaginertia="0.000139023 0.000109628 4.8478e-05"/>
      <joint name="left_joint1" pos="0 0 0" axis="0 0 1" range="-2.61799 3.05433" actuatorfrcrange="-100 100" armature="0.1" damping="0.5"/>
      <geom pos="-0.0464 0.0374968 0.119501" quat="0.499998 0.5 0.5 -0.500002" type="mesh" contype="0" conaffinity="0" rgba="0.72549 0.45098 0.317647 1" mesh="left_link1"/>
      <body name="left_link2" pos="-0.0329 0.02 0.0455" quat="0.499998 0.5 -0.500002 -0.5">
        <inertial pos="0.129165 0.000134495 -0.0321253" quat="0.499976 0.500008 0.500105 0.499911" mass="1.46908" diaginertia="0.0146686 0.014599 0.000800089"/>
        <joint name="left_joint2" pos="0 0 0" axis="0 0 1" range="0 3.65" actuatorfrcrange="-100 100" armature="0.1" damping="0.5"/>
        <geom pos="-0.0174977 -0.0740001 -0.07925" quat="0.499998 0.5 0.500002 0.5" type="mesh" contype="0" conaffinity="0" rgba="0 0.4 0.6 1" mesh="left_link2"/>
        <body name="left_link3" pos="0.264 4.08431e-07 -0.06375" quat="9.38184e-07 -0.707105 -0.707108 9.38187e-07">
          <inertial pos="0.0556042 -0.135083 -0.0340514" quat="0.704407 0.697077 0.121918 -0.0550519" mass="0.982553" diaginertia="0.00765198 0.0076296 0.000876442"/>
          <joint name="left_joint3" pos="0 0 0" axis="0 0 1" range="0 3.66519" actuatorfrcrange="-100 100" armature="0.1" damping="0.5"/>
          <geom pos="0.0740003 -0.281499 -0.0813" quat="9.38184e-07 9.38187e-07 -0.707108 -0.707105" type="mesh" contype="0" conaffinity="0" rgba="0.552941 0.580392 0.203922 1" mesh="left_link3"/>
          <body name="left_link4" pos="0.0600003 -0.244999 -0.00205" quat="1.32679e-06 0 0 -1">
            <inertial pos="-0.0543529 0.057068 -0.0332231" quat="0.636075 0.627088 0.370444 0.254833" mass="0.46678" diaginertia="0.000817855 0.000791274 0.000295776"/>
            <joint name="left_joint4" pos="0 0 0" axis="0 0 1" range="-1.5708 1.5708" actuatorfrcrange="-100 100" armature="0.1" damping="0.5"/>
            <geom pos="-0.0138003 0.0364989 -0.0787882" quat="0.707105 0.707108 0 0" type="mesh" contype="0" conaffinity="0" rgba="0.545098 0.52549 0.419608 1" mesh="left_link4"/>
            <body name="left_link5" pos="-0.0403003 0.0703851 -0.0323887" quat="9.38184e-07 -0.707105 -9.38187e-07 -0.707108">
              <inertial pos="-3.55003e-05 -0.00717397 0.0375847" quat="0.911516 0.411243 -0.00302177 -0.00303654" mass="0.403307" diaginertia="0.000219794 0.000195686 0.000169647"/>
              <joint name="left_joint5" pos="0 0 0" axis="0 0 1" range="-1.5708 1.5708" actuatorfrcrange="-100 100" armature="0.1" damping="0.5"/>
              <geom pos="-0.0463995 0.0311519 0.0265" quat="0.499998 -0.5 -0.5 -0.500002" type="mesh" contype="0" conaffinity="0" rgba="0.827451 0.623529 0.784314 1" mesh="left_link5"/>
              <body name="left_link6" pos="2.39858e-07 -0.0419481 0.0404996" quat="0.499998 -0.5 -0.5 -0.500002">
                <inertial pos="0 0 0" mass="0.1" diaginertia="0.0001 0.0001 0.0001"/>
                <joint name="left_joint6" pos="0 0 0" axis="0 0 -1" range="-2.0944 2.0944" actuatorfrcrange="-100 100" armature="0.1" damping="0.5"/>
                <body name="left_grasp" pos="0 0 -0.1347" quat="0 1 0 0">
                  <inertial pos="0 0 0" mass="0.01" diaginertia="1e-05 1e-05 1e-05"/>
                  <geom name="left_ee_palm" size="0.03 0.012 0.01" pos="0 0 -0.05" type="box" contype="0" conaffinity="0" rgba="0.95 0.5 0.1 1"/>
                  <geom name="left_ee_finger_a" size="0.006 0.006 0.025" pos="0.025 0 -0.025" type="box" contype="0" conaffinity="0" rgba="0.95 0.5 0.1 1"/>
                  <geom name="left_ee_finger_b" size="0.006 0.006 0.025" pos="-0.025 0 -0.025" type="box" contype="0" conaffinity="0" rgba="0.95 0.5 0.1 1"/>
                </body>
              </body>
            </body>
          </body>
        </body>
      </body>
    </body>
    <geom pos="-0.0374966 -0.396401 0.187501" quat="0.707105 0 0.707108 0" type="mesh" contype="0" conaffinity="0" rgba="0.317647 0.121569 0.498039 1" mesh="right_base"/>
    <body name="right_link1" pos="0 -0.35 0.067" quat="0.707105 0 0 -0.707108">
      <inertial pos="-0.00261782 0.00744082 0.0237251" quat="0.602276 0.365837 0.642523 0.300984" mass="0.104154" diaginertia="0.000139023 0.000109628 4.8478e-05"/>
      <joint name="right_joint1" pos="0 0 0" axis="0 0 1" range="-2.61799 3.05433" actuatorfrcrange="-100 100" armature="0.1" damping="0.5"/>
      <geom pos="-0.0464 0.0374968 0.119501" quat="0.499998 0.5 0.5 -0.500002" type="mesh" contype="0" conaffinity="0" rgba="0.72549 0.45098 0.317647 1" mesh="right_link1"/>
      <body name="right_link2" pos="-0.0329 0.02 0.0455" quat="0.499998 0.5 -0.500002 -0.5">
        <inertial pos="0.129165 0.000134495 -0.0321253" quat="0.499976 0.500008 0.500105 0.499911" mass="1.46908" diaginertia="0.0146686 0.014599 0.000800089"/>
        <joint name="right_joint2" pos="0 0 0" axis="0 0 1" range="0 3.65" actuatorfrcrange="-100 100" armature="0.1" damping="0.5"/>
        <geom pos="-0.0174977 -0.0740001 -0.07925" quat="0.499998 0.5 0.500002 0.5" type="mesh" contype="0" conaffinity="0" rgba="0 0.4 0.6 1" mesh="right_link2"/>
        <body name="right_link3" pos="0.264 4.08431e-07 -0.06375" quat="9.38184e-07 -0.707105 -0.707108 9.38187e-07">
          <inertial pos="0.0556042 -0.135083 -0.0340514" quat="0.704407 0.697077 0.121918 -0.0550519" mass="0.982553" diaginertia="0.00765198 0.0076296 0.000876442"/>
          <joint name="right_joint3" pos="0 0 0" axis="0 0 1" range="0 3.66519" actuatorfrcrange="-100 100" armature="0.1" damping="0.5"/>
          <geom pos="0.0740003 -0.281499 -0.0813" quat="9.38184e-07 9.38187e-07 -0.707108 -0.707105" type="mesh" contype="0" conaffinity="0" rgba="0.552941 0.580392 0.203922 1" mesh="right_link3"/>
          <body name="right_link4" pos="0.0600003 -0.244999 -0.00205" quat="1.32679e-06 0 0 -1">
            <inertial pos="-0.0543529 0.057068 -0.0332231" quat="0.636075 0.627088 0.370444 0.254833" mass="0.46678" diaginertia="0.000817855 0.000791274 0.000295776"/>
            <joint name="right_joint4" pos="0 0 0" axis="0 0 1" range="-1.5708 1.5708" actuatorfrcrange="-100 100" armature="0.1" damping="0.5"/>
            <geom pos="-0.0138003 0.0364989 -0.0787882" quat="0.707105 0.707108 0 0" type="mesh" contype="0" conaffinity="0" rgba="0.545098 0.52549 0.419608 1" mesh="right_link4"/>
            <body name="right_link5" pos="-0.0403003 0.0703851 -0.0323887" quat="9.38184e-07 -0.707105 -9.38187e-07 -0.707108">
              <inertial pos="-3.55003e-05 -0.00717397 0.0375847" quat="0.911516 0.411243 -0.00302177 -0.00303654" mass="0.403307" diaginertia="0.000219794 0.000195686 0.000169647"/>
              <joint name="right_joint5" pos="0 0 0" axis="0 0 1" range="-1.5708 1.5708" actuatorfrcrange="-100 100" armature="0.1" damping="0.5"/>
              <geom pos="-0.0463995 0.0311519 0.0265" quat="0.499998 -0.5 -0.5 -0.500002" type="mesh" contype="0" conaffinity="0" rgba="0.827451 0.623529 0.784314 1" mesh="right_link5"/>
              <body name="right_link6" pos="2.39858e-07 -0.0419481 0.0404996" quat="0.499998 -0.5 -0.5 -0.500002">
                <inertial pos="0 0 0" mass="0.1" diaginertia="0.0001 0.0001 0.0001"/>
                <joint name="right_joint6" pos="0 0 0" axis="0 0 -1" range="-2.0944 2.0944" actuatorfrcrange="-100 100" armature="0.1" damping="0.5"/>
                <body name="right_grasp" pos="0 0 -0.1347" quat="0 1 0 0">
                  <inertial pos="0 0 0" mass="0.01" diaginertia="1e-05 1e-05 1e-05"/>
                  <geom name="right_ee_palm" size="0.03 0.012 0.01" pos="0 0 -0.05" type="box" contype="0" conaffinity="0" rgba="0.95 0.5 0.1 1"/>
                  <geom name="right_ee_finger_a" size="0.006 0.006 0.025" pos="0.025 0 -0.025" type="box" contype="0" conaffinity="0" rgba="0.95 0.5 0.1 1"/>
                  <geom name="right_ee_finger_b" size="0.006 0.006 0.025" pos="-0.025 0 -0.025" type="box" contype="0" conaffinity="0" rgba="0.95 0.5 0.1 1"/>
                </body>
              </body>
            </body>
          </body>
        </body>
      </body>
    </body>
  </worldbody>

  <actuator>
    <general name="left_joint1" joint="left_joint1" biastype="affine" gainprm="500" biasprm="0 -500 -15"/>
    <general name="left_joint2" joint="left_joint2" biastype="affine" gainprm="500" biasprm="0 -500 -15"/>
    <general name="left_joint3" joint="left_joint3" biastype="affine" gainprm="400" biasprm="0 -400 -13"/>
    <general name="left_joint4" joint="left_joint4" biastype="affine" gainprm="150" biasprm="0 -150 -8"/>
    <general name="left_joint5" joint="left_joint5" biastype="affine" gainprm="150" biasprm="0 -150 -8"/>
    <general name="left_joint6" joint="left_joint6" biastype="affine" gainprm="100" biasprm="0 -100 -6"/>
    <general name="right_joint1" joint="right_joint1" biastype="affine" gainprm="500" biasprm="0 -500 -15"/>
    <general name="right_joint2" joint="right_joint2" biastype="affine" gainprm="500" biasprm="0 -500 -15"/>
    <general name="right_joint3" joint="right_joint3" biastype="affine" gainprm="400" biasprm="0 -400 -13"/>
    <general name="right_joint4" joint="right_joint4" biastype="affine" gainprm="150" biasprm="0 -150 -8"/>
    <general name="right_joint5" joint="right_joint5" biastype="affine" gainprm="150" biasprm="0 -150 -8"/>
    <general name="right_joint6" joint="right_joint6" biastype="affine" gainprm="100" biasprm="0 -100 -6"/>
  </actuator>

  <keyframe>
    <key name="home" qpos="-0.02842 0.00134 0 -0.10014 -0.0555 -0.22717 -0.02842 0.00134 0 -0.10014 -0.0555 -0.22717" ctrl="-0.02842 0.00134 0 -0.10014 -0.0555 -0.22717 -0.02842 0.00134 0 -0.10014 -0.0555 -0.22717"/>
  </keyframe>
</mujoco>
